Workbook

Sheet 费用明细
A1: 格鲁吉亚 · 亚美尼亚 · 乌兹别克斯坦 旅行费用明细
A2: 2026.9.18 – 10.4 · 2 人 · 所有外币按下方汇率自动换算人民币
A4: 汇率表 | C4: ← 黄色格子是你要填/改的，其余是公式，别动
A5: 币种 | B5: 代码 | C5: 1 单位 = 人民币
A6: 人民币 | B6: CNY | C6: 1
A7: 美元 | B7: USD | C7: 7.1
A8: 格鲁吉亚拉里 | B8: GEL | C8: 2.63
A9: 亚美尼亚德拉姆 | B9: AMD | C9: 0.018
A10: 乌兹别克苏姆 | B10: UZS | C10: 0.00056
A12: 汇率来源日期： | C12: （填写查询日期）
A14: 日期 | B14: 类别 | C14: 项目 | D14: 说明 | E14: 单价 | F14: 币种 | G14: 数量 | H14: 原币小计 | I14: 汇率 | J14: 人民币 | K14: 状态 | L14: 支付方式
B15: 国际机票 | C15: MU285 浦东 → 第比利斯 | D15: 9.18 12:50–19:00 | F15: CNY | G15: 2 | H15: =IF(E15="","",E15*G15) | I15: =IF(F15="","",IFERROR(INDEX($C$6:$C$10,MATCH(F15,$B$6:$B$10,0)),"查无此币种")) | J15: =IF(H15="","",H15*I15) | K15: 待填
B16: 国际机票 | C16: C6222 第比利斯 → 塔什干 | D16: 10.1 15:30–19:50 | F16: CNY | G16: 2 | H16: =IF(E16="","",E16*G16) | I16: =IF(F16="","",IFERROR(INDEX($C$6:$C$10,MATCH(F16,$B$6:$B$10,0)),"查无此币种")) | J16: =IF(H16="","",H16*I16) | K16: 待填
B17: 国际机票 | C17: MU6038 塔什干 → 浦东 | D17: 10.3 20:20–05:50+1 | F17: CNY | G17: 2 | H17: =IF(E17="","",E17*G17) | I17: =IF(F17="","",IFERROR(INDEX($C$6:$C$10,MATCH(F17,$B$6:$B$10,0)),"查无此币种")) | J17: =IF(H17="","",H17*I17) | K17: 待填
B18: 保险 | C18: 境外旅行险 | D18: 须含亚美尼亚+乌兹别克，保额≥30,000 GEL | F18: CNY | G18: 2 | H18: =IF(E18="","",E18*G18) | I18: =IF(F18="","",IFERROR(INDEX($C$6:$C$10,MATCH(F18,$B$6:$B$10,0)),"查无此币种")) | J18: =IF(H18="","",H18*I18) | K18: 待填
A19: 9.18 | B19: 住宿 | C19: 第比利斯 · Avlabari | D19: 5 晚 9.18–9.23 | F19: GEL | G19: 5 | H19: =IF(E19="","",E19*G19) | I19: =IF(F19="","",IFERROR(INDEX($C$6:$C$10,MATCH(F19,$B$6:$B$10,0)),"查无此币种")) | J19: =IF(H19="","",H19*I19) | K19: 待订
A20: 9.23 | B20: 住宿 | C20: 巴统希尔顿 | D20: 1 晚，海景特大床，确认号 3522841428 | E20: 179.95 | F20: USD | G20: 1 | H20: =IF(E20="","",E20*G20) | I20: =IF(F20="","",IFERROR(INDEX($C$6:$C$10,MATCH(F20,$B$6:$B$10,0)),"查无此币种")) | J20: =IF(H20="","",H20*I20) | K20: 已付 | L20: Visa 3159
A21: 9.24 | B21: 住宿 | C21: 巴统民宿 42 Rustaveli Ave | D21: 2 晚 9.24–9.26 | F21: GEL | G21: 2 | H21: =IF(E21="","",E21*G21) | I21: =IF(F21="","",IFERROR(INDEX($C$6:$C$10,MATCH(F21,$B$6:$B$10,0)),"查无此币种")) | J21: =IF(H21="","",H21*I21) | K21: 待填
A22: 9.26 | B22: 住宿 | C22: Monograph Freedom Square | D22: 1 晚，订单号 1128150691023697 | F22: CNY | G22: 1 | H22: =IF(E22="","",E22*G22) | I22: =IF(F22="","",IFERROR(INDEX($C$6:$C$10,MATCH(F22,$B$6:$B$10,0)),"查无此币种")) | J22: =IF(H22="","",H22*I22) | K22: 待填 | L22: 携程
A23: 9.27 | B23: 住宿 | C23: 埃里温 | D23: 3 晚，朋友安排 | F23: AMD | G23: 3 | H23: =IF(E23="","",E23*G23) | I23: =IF(F23="","",IFERROR(INDEX($C$6:$C$10,MATCH(F23,$B$6:$B$10,0)),"查无此币种")) | J23: =IF(H23="","",H23*I23) | K23: 待填
A24: 9.30 | B24: 住宿 | C24: 第比利斯 · 最后一晚 | D24: 1 晚 9.30–10.1 | F24: GEL | G24: 1 | H24: =IF(E24="","",E24*G24) | I24: =IF(F24="","",IFERROR(INDEX($C$6:$C$10,MATCH(F24,$B$6:$B$10,0)),"查无此币种")) | J24: =IF(H24="","",H24*I24) | K24: 待订
A25: 10.1 | B25: 住宿 | C25: 塔什干 | D25: 2 晚 10.1–10.3 | F25: UZS | G25: 2 | H25: =IF(E25="","",E25*G25) | I25: =IF(F25="","",IFERROR(INDEX($C$6:$C$10,MATCH(F25,$B$6:$B$10,0)),"查无此币种")) | J25: =IF(H25="","",H25*I25) | K25: 待订
A26: 9.23 | B26: 城际交通 | C26: 火车 第比利斯 → 巴统 | D26: 08:00–12:00，经济舱。一等舱 $29.03 | E26: 13.75 | F26: USD | G26: 2 | H26: =IF(E26="","",E26*G26) | I26: =IF(F26="","",IFERROR(INDEX($C$6:$C$10,MATCH(F26,$B$6:$B$10,0)),"查无此币种")) | J26: =IF(H26="","",H26*I26) | K26: 待订 | L26: tkt.ge
A27: 9.25 | B27: 城际交通 | C27: 包车 阿扎拉山区往返 | D27: Nodar / Highlander / DD-971-PD | F27: GEL | G27: 1 | H27: =IF(E27="","",E27*G27) | I27: =IF(F27="","",IFERROR(INDEX($C$6:$C$10,MATCH(F27,$B$6:$B$10,0)),"查无此币种")) | J27: =IF(H27="","",H27*I27) | K27: 待付 | L27: 建议现金
A28: 9.26 | B28: 城际交通 | C28: 包车 巴统 → 第比利斯 | D28: Vladimer / Accord / VL-102-AD，443km | E28: 179 | F28: USD | G28: 1 | H28: =IF(E28="","",E28*G28) | I28: =IF(F28="","",IFERROR(INDEX($C$6:$C$10,MATCH(F28,$B$6:$B$10,0)),"查无此币种")) | J28: =IF(H28="","",H28*I28) | K28: 待付 | L28: 建议现金
A29: 9.27 | B29: 城际交通 | C29: 第比利斯 → 埃里温 | D29: 小巴/大巴/包车，朋友安排 | F29: USD | G29: 2 | H29: =IF(E29="","",E29*G29) | I29: =IF(F29="","",IFERROR(INDEX($C$6:$C$10,MATCH(F29,$B$6:$B$10,0)),"查无此币种")) | J29: =IF(H29="","",H29*I29) | K29: 待填
A30: 9.30 | B30: 城际交通 | C30: 埃里温 → 第比利斯 | D30: 建议包车，参考 100–150 USD 一车 | F30: USD | G30: 1 | H30: =IF(E30="","",E30*G30) | I30: =IF(F30="","",IFERROR(INDEX($C$6:$C$10,MATCH(F30,$B$6:$B$10,0)),"查无此币种")) | J30: =IF(H30="","",H30*I30) | K30: 待订
A31: 10.2 | B31: 城际交通 | C31: Afrosiyob 高铁 塔什干⇄撒马尔罕 | D31: 往返，需提前 60 天买 | F31: UZS | G31: 2 | H31: =IF(E31="","",E31*G31) | I31: =IF(F31="","",IFERROR(INDEX($C$6:$C$10,MATCH(F31,$B$6:$B$10,0)),"查无此币种")) | J31: =IF(H31="","",H31*I31) | K31: 待订 | L31: railway.uz
A32: 9.18 | B32: 市内交通 | C32: 机场 → Avlabari | D32: Bolt，约 25–35 GEL | E32: 30 | F32: GEL | G32: 1 | H32: =IF(E32="","",E32*G32) | I32: =IF(F32="","",IFERROR(INDEX($C$6:$C$10,MATCH(F32,$B$6:$B$10,0)),"查无此币种")) | J32: =IF(H32="","",H32*I32) | K32: 预估 | L32: 现金/App
B33: 市内交通 | C33: 第比利斯市内 Bolt + 地铁 | D33: 5 天，含姆茨赫塔往返约 60 GEL | E33: 150 | F33: GEL | G33: 1 | H33: =IF(E33="","",E33*G33) | I33: =IF(F33="","",IFERROR(INDEX($C$6:$C$10,MATCH(F33,$B$6:$B$10,0)),"查无此币种")) | J33: =IF(H33="","",H33*I33) | K33: 预估
A34: 9.23 | B34: 市内交通 | C34: 巴统站 → 市区 + 植物园往返 | D34: 约 10–15 + 30–40 GEL | E34: 55 | F34: GEL | G34: 1 | H34: =IF(E34="","",E34*G34) | I34: =IF(F34="","",IFERROR(INDEX($C$6:$C$10,MATCH(F34,$B$6:$B$10,0)),"查无此币种")) | J34: =IF(H34="","",H34*I34) | K34: 预估
A35: 10.1 | B35: 市内交通 | C35: 第比利斯 → 机场 | D35: Bolt，约 25–35 GEL | E35: 30 | F35: GEL | G35: 1 | H35: =IF(E35="","",E35*G35) | I35: =IF(F35="","",IFERROR(INDEX($C$6:$C$10,MATCH(F35,$B$6:$B$10,0)),"查无此币种")) | J35: =IF(H35="","",H35*I35) | K35: 预估
B36: 市内交通 | C36: 塔什干 Yandex Go | D36: 机场往返 + 市内，3 天 | F36: UZS | G36: 1 | H36: =IF(E36="","",E36*G36) | I36: =IF(F36="","",IFERROR(INDEX($C$6:$C$10,MATCH(F36,$B$6:$B$10,0)),"查无此币种")) | J36: =IF(H36="","",H36*I36) | K36: 待填
A37: 9.19 | B37: 一日游 | C37: 卡兹别吉深度小团 | D37: 携程，6 人小团 + 4×4，含特鲁索峡谷 | F37: CNY | G37: 2 | H37: =IF(E37="","",E37*G37) | I37: =IF(F37="","",IFERROR(INDEX($C$6:$C$10,MATCH(F37,$B$6:$B$10,0)),"查无此币种")) | J37: =IF(H37="","",H37*I37) | K37: 已订 | L37: 携程
A38: 9.20 | B38: 一日游 | C38: 卡赫季酒乡一日 | D38: 欧洲广场 08:45 集合，特拉维品 9 种酒 | F38: CNY | G38: 2 | H38: =IF(E38="","",E38*G38) | I38: =IF(F38="","",IFERROR(INDEX($C$6:$C$10,MATCH(F38,$B$6:$B$10,0)),"查无此币种")) | J38: =IF(H38="","",H38*I38) | K38: 已订
A39: 9.20 | B39: 一日游 | C39: 卡赫季 · 酒庄午餐 | D39: 特拉维餐厅按菜单另付 | F39: GEL | G39: 2 | H39: =IF(E39="","",E39*G39) | I39: =IF(F39="","",IFERROR(INDEX($C$6:$C$10,MATCH(F39,$B$6:$B$10,0)),"查无此币种")) | J39: =IF(H39="","",H39*I39) | K39: 待填 | L39: 现金
A40: 9.24 | B40: 一日游 | C40: 巴统美食漫步（可选） | D40: Airbnb 5h，★4.88 / 36 评价 | E40: 195 | F40: CNY | G40: 2 | H40: =IF(E40="","",E40*G40) | I40: =IF(F40="","",IFERROR(INDEX($C$6:$C$10,MATCH(F40,$B$6:$B$10,0)),"查无此币种")) | J40: =IF(H40="","",H40*I40) | K40: 可选
A41: 9.25 | B41: 一日游 | C41: Keda 酒庄品鉴 + 午餐 | D41: 包车不含，现场付 | F41: GEL | G41: 2 | H41: =IF(E41="","",E41*G41) | I41: =IF(F41="","",IFERROR(INDEX($C$6:$C$10,MATCH(F41,$B$6:$B$10,0)),"查无此币种")) | J41: =IF(H41="","",H41*I41) | K41: 待填 | L41: 现金
A42: 9.21 | B42: 门票娱乐 | C42: 硫磺浴私人包间 | D42: 60–120 GEL/小时，搓背另加 15–20 | E42: 90 | F42: GEL | G42: 1 | H42: =IF(E42="","",E42*G42) | I42: =IF(F42="","",IFERROR(INDEX($C$6:$C$10,MATCH(F42,$B$6:$B$10,0)),"查无此币种")) | J42: =IF(H42="","",H42*I42) | K42: 预估 | L42: 现金
A43: 9.21 | B43: 门票娱乐 | C43: Narikala 缆车 | D43: 2.5 GEL/人，只收 Metromoney 卡 | E43: 2.5 | F43: GEL | G43: 2 | H43: =IF(E43="","",E43*G43) | I43: =IF(F43="","",IFERROR(INDEX($C$6:$C$10,MATCH(F43,$B$6:$B$10,0)),"查无此币种")) | J43: =IF(H43="","",H43*I43) | K43: 预估 | L43: Metromoney
...

Sheet 汇总
A1: 费用汇总
A2: 全部由「费用明细」自动汇总，不用手工填
A4: 按类别
A5: 项目 | B5: 人民币 | C5: 占比
A6: 国际机票 | B6: =SUMIFS(费用明细!$J$15:$J$57,费用明细!$B$15:$B$57,$A6) | C6: =IF(费用明细!$J$58=0,0,B6/费用明细!$J$58)
A7: 保险 | B7: =SUMIFS(费用明细!$J$15:$J$57,费用明细!$B$15:$B$57,$A7) | C7: =IF(费用明细!$J$58=0,0,B7/费用明细!$J$58)
A8: 住宿 | B8: =SUMIFS(费用明细!$J$15:$J$57,费用明细!$B$15:$B$57,$A8) | C8: =IF(费用明细!$J$58=0,0,B8/费用明细!$J$58)
A9: 城际交通 | B9: =SUMIFS(费用明细!$J$15:$J$57,费用明细!$B$15:$B$57,$A9) | C9: =IF(费用明细!$J$58=0,0,B9/费用明细!$J$58)
A10: 市内交通 | B10: =SUMIFS(费用明细!$J$15:$J$57,费用明细!$B$15:$B$57,$A10) | C10: =IF(费用明细!$J$58=0,0,B10/费用明细!$J$58)
A11: 一日游 | B11: =SUMIFS(费用明细!$J$15:$J$57,费用明细!$B$15:$B$57,$A11) | C11: =IF(费用明细!$J$58=0,0,B11/费用明细!$J$58)
A12: 门票娱乐 | B12: =SUMIFS(费用明细!$J$15:$J$57,费用明细!$B$15:$B$57,$A12) | C12: =IF(费用明细!$J$58=0,0,B12/费用明细!$J$58)
A13: 餐饮 | B13: =SUMIFS(费用明细!$J$15:$J$57,费用明细!$B$15:$B$57,$A13) | C13: =IF(费用明细!$J$58=0,0,B13/费用明细!$J$58)
A14: 通讯 | B14: =SUMIFS(费用明细!$J$15:$J$57,费用明细!$B$15:$B$57,$A14) | C14: =IF(费用明细!$J$58=0,0,B14/费用明细!$J$58)
A15: 购物 | B15: =SUMIFS(费用明细!$J$15:$J$57,费用明细!$B$15:$B$57,$A15) | C15: =IF(费用明细!$J$58=0,0,B15/费用明细!$J$58)
A16: 其他 | B16: =SUMIFS(费用明细!$J$15:$J$57,费用明细!$B$15:$B$57,$A16) | C16: =IF(费用明细!$J$58=0,0,B16/费用明细!$J$58)
A17: 小计 | B17: =SUM(B6:B16) | C17: =IF(费用明细!$J$58=0,0,B17/费用明细!$J$58)
A19: 按状态
A20: 项目 | B20: 人民币 | C20: 占比
A21: 已付 | B21: =SUMIFS(费用明细!$J$15:$J$57,费用明细!$K$15:$K$57,$A21) | C21: =IF(费用明细!$J$58=0,0,B21/费用明细!$J$58)
A22: 已订 | B22: =SUMIFS(费用明细!$J$15:$J$57,费用明细!$K$15:$K$57,$A22) | C22: =IF(费用明细!$J$58=0,0,B22/费用明细!$J$58)
A23: 待付 | B23: =SUMIFS(费用明细!$J$15:$J$57,费用明细!$K$15:$K$57,$A23) | C23: =IF(费用明细!$J$58=0,0,B23/费用明细!$J$58)
A24: 待订 | B24: =SUMIFS(费用明细!$J$15:$J$57,费用明细!$K$15:$K$57,$A24) | C24: =IF(费用明细!$J$58=0,0,B24/费用明细!$J$58)
A25: 待填 | B25: =SUMIFS(费用明细!$J$15:$J$57,费用明细!$K$15:$K$57,$A25) | C25: =IF(费用明细!$J$58=0,0,B25/费用明细!$J$58)
A26: 预估 | B26: =SUMIFS(费用明细!$J$15:$J$57,费用明细!$K$15:$K$57,$A26) | C26: =IF(费用明细!$J$58=0,0,B26/费用明细!$J$58)
A27: 可选 | B27: =SUMIFS(费用明细!$J$15:$J$57,费用明细!$K$15:$K$57,$A27) | C27: =IF(费用明细!$J$58=0,0,B27/费用明细!$J$58)
A28: 小计 | B28: =SUM(B21:B27) | C28: =IF(费用明细!$J$58=0,0,B28/费用明细!$J$58)
A30: 按币种（原币金额，便于备现金）
A31: 币种 | B31: 原币合计 | C31: 折人民币
A32: CNY | B32: =SUMIFS(费用明细!$H$15:$H$57,费用明细!$F$15:$F$57,$A32) | C32: =SUMIFS(费用明细!$J$15:$J$57,费用明细!$F$15:$F$57,$A32)
A33: USD | B33: =SUMIFS(费用明细!$H$15:$H$57,费用明细!$F$15:$F$57,$A33) | C33: =SUMIFS(费用明细!$J$15:$J$57,费用明细!$F$15:$F$57,$A33)
A34: GEL | B34: =SUMIFS(费用明细!$H$15:$H$57,费用明细!$F$15:$F$57,$A34) | C34: =SUMIFS(费用明细!$J$15:$J$57,费用明细!$F$15:$F$57,$A34)
A35: AMD | B35: =SUMIFS(费用明细!$H$15:$H$57,费用明细!$F$15:$F$57,$A35) | C35: =SUMIFS(费用明细!$J$15:$J$57,费用明细!$F$15:$F$57,$A35)
A36: UZS | B36: =SUMIFS(费用明细!$H$15:$H$57,费用明细!$F$15:$F$57,$A36) | C36: =SUMIFS(费用明细!$J$15:$J$57,费用明细!$F$15:$F$57,$A36)
A38: 总计 | B38: =费用明细!$J$58
A39: 人均（2 人） | B39: =费用明细!$J$58/2
A40: 剩余待付（不含已付） | B40: =费用明细!$J$58-SUMIFS(费用明细!$J$15:$J$57,费用明细!$K$15:$K$57,"已付")
